[2025-06-12T18:18:21.689080] Failed to log event: test_write
Traceback (most recent call last):
  File "/home/itsjayhani/logger_v23.py", line 343, in log_event
    os.makedirs(os.path.dirname(EVENT_LOG_FILE), exist_ok=True)
  File "<frozen os>", line 225, in makedirs
FileNotFoundError: [Errno 2] No such file or directory: ''

---
[2025-06-12T18:19:21.693019] Failed to log event: test_write
Traceback (most recent call last):
  File "/home/itsjayhani/logger_v23.py", line 343, in log_event
    os.makedirs(os.path.dirname(EVENT_LOG_FILE), exist_ok=True)
  File "<frozen os>", line 225, in makedirs
FileNotFoundError: [Errno 2] No such file or directory: ''

---
[2025-06-12T18:20:21.695360] Failed to log event: test_write
Traceback (most recent call last):
  File "/home/itsjayhani/logger_v23.py", line 343, in log_event
    os.makedirs(os.path.dirname(EVENT_LOG_FILE), exist_ok=True)
  File "<frozen os>", line 225, in makedirs
FileNotFoundError: [Errno 2] No such file or directory: ''

---
